<?xml version="1.0"?>
<robot  xmlns:xacro="http://ros.org/wiki/xacro"
        name="kownbot" >
    <xacro:include filename="$(find kownbot_description)/urdf/kinect.xacro" /> 
     <xacro:include filename="$(find kownbot_description)/urdf/kownbot_gazebo.gazebo" /> 
    <xacro:include filename="$(find kownbot_description)/urdf/materials.urdf.xacro" />


    <xacro:arg name="mesh_enabled" default="false" />
    <xacro:arg name="robot_namespace" default="/"/>
  
  
  <link   name =  "base_footprint"/>


    <joint name = "base_joint"  type = "fixed">
        <parent link="base_footprint"/>
        <child link="base_link"/>
        <origin xyz="0.0 0.0 0.07" rpy="0 0 0" />
        <axis xyz="0 1 0" rpy="0 0 0" />
    </joint>

  <link name="base_link">
    <inertial>
      <origin
        xyz="0.011330126346242 -0.000181604320492565 -0.022651852902026"
        rpy="0 0 0" />
      <mass
        value="1.53903472410721" />
      <inertia
        ixx="0.00077903219158376"
        ixy="2.08942350289896E-07"
        ixz="8.08564456080161E-08"
        iyy="0.000922696056233437"
        iyz="-1.05452446874585E-07"
        izz="0.00134199119233453" />
    </inertial>
    <visual>
      <origin
        xyz="0 0 0"
        rpy="0 0 0" />
      <geometry>
        <mesh
          filename="package://kownbot_description/meshes/base_link.STL" />
      </geometry>
      
    </visual>
    <collision>
      <origin
        xyz="0 0 0"
        rpy="0 0 0" />
      <geometry>
        <mesh
          filename="package://kownbot_description/meshes/base_link.STL" />
      </geometry>
    </collision>
  </link>

  <link
    name="left_wheel">
    <inertial>
      <origin
        xyz="2.113394875769E-10 0.0177680510267829 -1.68064256955702E-10"
        rpy="0 0 0" />
      <mass
        value="0.0967290535266856" />
      <inertia
        ixx="7.18602975356282E-05"
        ixy="3.61464994908879E-13"
        ixz="2.91883480864273E-13"
        iyy="0.000118262105464773"
        iyz="-1.28873302031774E-13"
        izz="7.18602979134469E-05" />
    </inertial>
    <visual>
      <origin
        xyz="0 0 0"
        rpy="0 0 0" />
      <geometry>
        <mesh
          filename="package://kownbot_description/meshes/left_wheel.STL" />
      </geometry>
      <material
        name="">
        <color
          rgba="0.792156862745098 0.819607843137255 0.933333333333333 1" />
      </material>
    </visual>
    <collision>
      <origin
        xyz="0 0 0"
        rpy="0 0 0" />
      <geometry>
        <mesh
          filename="package://kownbot_description/meshes/left_wheel.STL" />
      </geometry>
    </collision>
  </link>
  <joint
    name="left_wheel_joint"
    type="continuous">
    <origin
      xyz="0 0.071668 -0.0284"
      rpy="0 0 0" />
    <parent
      link="base_link" />
    <child
      link="left_wheel" />
    <axis
      xyz="0 1 0"  rpy="0 0 0"/>
  </joint>
  
  <transmission name="left_wheel_trans" type="SimpleTransmission">
      <type>hardware_interface/VelocityJointInterface</type>
	<actuator name="left_wheel_motor">
	   <mechanicalReduction>1</mechanicalReduction>
	</actuator>
	<joint name="left_wheel_joint">
	   <hardwareInterface>hardware_interface/VelocityJointInterface</hardwareInterface>
	</joint>
  </transmission>
		
		
		
		
  <link
    name="right_wheel">
    <inertial>
      <origin
        xyz="-1.56448132226927E-10 -0.017768051026074 -3.36882327589549E-10"
        rpy="0 0 0" />
      <mass
        value="0.0967290535274189" />
      <inertia
        ixx="7.18602977346931E-05"
        ixy="3.17497192852541E-13"
        ixz="-3.48076824472087E-13"
        iyy="0.000118262105464592"
        iyz="2.68279255047089E-13"
        izz="7.18602977142813E-05" />
    </inertial>
    <visual>
      <origin
        xyz="0 0 0"
        rpy="0 0 0" />
      <geometry>
        <mesh
          filename="package://kownbot_description/meshes/right_wheel.STL" />
      </geometry>
      <material
        name="">
        <color
          rgba="0.792156862745098 0.819607843137255 0.933333333333333 1" />
      </material>
    </visual>
    <collision>
      <origin
        xyz="0 0 0"
        rpy="0 0 0" />
      <geometry>
        <mesh
          filename="package://kownbot_description/meshes/right_wheel.STL" />
      </geometry>
    </collision>
  </link>
  <joint
    name="right_wheel_joint"
    type="continuous">
    <origin
      xyz="0 -0.0716681397513279 -0.0284000000437361"
      rpy="0 0 0" />
    <parent
      link="base_link" />
    <child
      link="right_wheel" />
    <axis
      xyz="0 1 0"  rpy="0 0 0"/>
  </joint>
<transmission name="right_wheel_trans" type="SimpleTransmission">
      <type>hardware_interface/VelocityJointInterface</type>
	<actuator name="right_wheel_motor">
	   <mechanicalReduction>1</mechanicalReduction>
	</actuator>
	<joint name="right_wheel_joint">
	   <hardwareInterface>hardware_interface/VelocityJointInterface</hardwareInterface>
	</joint>
  </transmission>


  

    <xacro:sensor_kinect parent="base_link" />
    
    <gazebo>
        <plugin name="gazebo_ros_control" filename="libgazebo_ros_control.so">
        <robotNamespace>$(arg robot_namespace)</robotNamespace>
        <legacyModeNS>true</legacyModeNS>
        </plugin>
    </gazebo>



    


    




</robot>
